Workbook
Name ABANCAY: DPTOS!$C$252:$C$260
Name ACOBAMBA: DPTOS!$C$810:$C$817
Name ACOMAYO: DPTOS!$C$698:$C$704
Name AIJA: DPTOS!$C$86:$C$90
Name ALTO_AMAZONAS: DPTOS!$C$1453:$C$1458
Name AMAZONAS: DPTOS!$B$2:$B$8
Name AMBO: DPTOS!$C$910:$C$917
Name ANCASH: DPTOS!$B$9:$B$28
Name ANDAHUAYLAS: DPTOS!$C$261:$C$280
Name ANGARES: DPTOS!$C$818:$C$829
Name ANTA: DPTOS!$C$705:$C$713
Name ANTABAMBA: DPTOS!$C$281:$C$287
Name ANTONIO_RAYMONDI: DPTOS!$C$91:$C$96
Name APURIMAC: DPTOS!$B$29:$B$35
Name AREQUIPA: DPTOS!$B$36:$B$43
Name AREQUIPA.: DPTOS!$C$336:$C$364
Name ASCOPE: DPTOS!$C$1161:$C$1168
Name ASUNCION: DPTOS!$C$97:$C$98
Name ATALAYA: DPTOS!$C$1859:$C$1862
Name AYABACA: DPTOS!$C$1566:$C$1575
Name AYACUCHO: DPTOS!$B$44:$B$54
Name AYMARAES: DPTOS!$C$288:$C$304
Name AZANGARO: DPTOS!$C$1631:$C$1645
Name BAGUA: DPTOS!$C$2:$C$7
Name BARRANCA: DPTOS!$C$1282:$C$1286
Name BELLAVISTA: DPTOS!$C$1741:$C$1746
Name BOLIVAR: DPTOS!$C$1169:$C$1174
Name BOLOGNESI: DPTOS!$C$99:$C$113
Name BONGARA: DPTOS!$C$8:$C$19
Name CAJAMARCA: DPTOS!$B$55:$B$67
Name CAJAMARCA.: DPTOS!$C$564:$C$579
Name CAJATAMBO: DPTOS!$C$1287:$C$1291
Name CALCA: DPTOS!$C$714:$C$721
Name CALLAO: DPTOS!$B$68
Name CALLAO.: DPTOS!$C$691:$C$697
Name CAMANA: DPTOS!$C$365:$C$372
Name CANAS: DPTOS!$C$722:$C$729
Name CANCHIS: DPTOS!$C$730:$C$737
Name CANDARAVE: DPTOS!$C$1818:$C$1823
Name CANGALLO: DPTOS!$C$445:$C$450
Name CANTA: DPTOS!$C$1292:$C$1298
Name CAÑETE: DPTOS!$C$1299:$C$1314
Name CARABAYA: DPTOS!$C$1646:$C$1655
Name CARAVELI: DPTOS!$C$373:$C$385
Name CARHUAZ: DPTOS!$C$114:$C$124
Name CARLOS_FERMIN_FITZCARRALD: DPTOS!$C$125:$C$127
Name CASMA: DPTOS!$C$128:$C$131
Name CASTILLA: DPTOS!$C$386:$C$399
Name CASTROVIRREYNA: DPTOS!$C$830:$C$842
Name CAYLLOMA: DPTOS!$C$400:$C$419
Name CELEDIN: DPTOS!$C$580:$C$591
Name CHACHAPOYAS: DPTOS!$C$20:$C$40
Name CHANCHAMAYO: DPTOS!$C$1037:$C$1042
Name CHEPEN: DPTOS!$C$1175:$C$1177
Name CHICLAYO: DPTOS!$C$1244:$C$1263
Name CHINCHA: DPTOS!$C$994:$C$1004
Name CHINCHEROS: DPTOS!$C$305:$C$315
Name CHOTA: DPTOS!$C$592:$C$610
Name CHUCUITO: DPTOS!$C$1656:$C$1662
Name CHUMBIVILCAS: DPTOS!$C$738:$C$745

Sheet MEMORIA Y VAL
S10: =+R94 -> INFORME N°26 | AB10: =+AB94 -> 0
A11: =+A95 -> "VALUACIÓN COMERCIAL DE INMUEBLE "
A12: =+A97 -> CLIENTE DEL | O12: : | P12: =+S97 -> 0
A13: =+A98 -> PROPIETARIO | O13: : | P13: =+S98 -> 0
A14: LEGAJO N° | O14: : | P14: =+HR!F3 -> 0
A15: Ubicación | F15: =+C110 -> Según Ficha Registral | O15: : | P15: =+C111 -> 0
F16: =+C112 -> Según Autoavalúo | O16: : | P16: =+C113 -> 0
F17: =+C114 -> Según Inspección ocular | O17: : | P17: =+C115 -> 0
A21: PLANO Y FACHADA
A34: GEOREFERENCIAS | O34: : | P34: Latitud | AF34: Longitud
A36: VALORES DÓLARES AMERICANOS
A38: DESCRIPCIÓN | K38: Área Terreno (m²) | O38: Valor Terreno US$ | U38: Área Const. (m²) | Y38: Valor Construcción US$ | AE38: Valor Importe Asegurable US$ | AK38: Valor Comercial US$ | AQ38: Valor Realización US$
A39: Detalle de áreas declaradas en Partida registral
A40: =+C327 -> Primer piso | K40: =+AO130 -> 0 | O40: =+AM444 -> 0 | U40: =+C328 -> 0 | Y40: =+AO328+AO336+AO349 -> 0 | AE40: =+AO364+AO372+AO385 -> 0 | AK40: =+(O40+Y40)*E$452 -> 0 | AQ40: =ROUND(AK40*I$466,1) -> 0
A41: =+C329 -> Segundo piso | K41: 0 | O41: 0 | U41: =+C330 -> 0 | Y41: =+AO330 -> 0 | AE41: =+AO366 -> 0 | AK41: =+Y41*E$452 -> 0 | AQ41: =ROUND(AK41*I$466,1) -> 0
A42: =+C331 -> Tercer piso | K42: 0 | O42: 0 | U42: =+C332 -> 0 | Y42: =+AO332 -> 0 | AE42: =+AO368 -> 0 | AK42: =+Y42*E$452 -> 0 | AQ42: =ROUND(AK42*I$466,1) -> 0
A43: =+C183 -> Estacionamiento Nº.. | K43: =+AO132 -> 0 | O43: 0 | U43: =+N183 -> 0 | Y43: 0 | AE43: =+AM481 -> 0 | AK43: =+AM453 -> 0 | AQ43: =ROUND(AK43*I$466,1) -> 0
A44: =+C184 -> Depósito Nº … | K44: =+AO134 -> 0 | O44: 0 | U44: =+N184 -> 0 | Y44: 0 | AE44: =+AM482 -> 0 | AK44: =+AM454 -> 0 | AQ44: =ROUND(AK44*I$466,1) -> 0
A45: Total Declarado en Partida Registral | K45: =+K40 -> 0 | O45: =ROUND(SUM(O40:T44),1) -> 0 | U45: =SUM(U40:X44) -> 0 | Y45: =ROUND(SUM(Y40:AD44),1) -> 0 | AE45: =ROUND(SUM(AE40:AJ44),1) -> 0 | AK45: =ROUND(SUM(AK40:AP44),1) -> 0 | AQ45: =ROUND(SUM(AQ40:AV44),1) -> 0
A46: Detalle de áreas declaradas en Autoavalúo
A47: =+C714 -> Primer piso | K47: 0 | O47: 0 | U47: =+C715 -> 0 | Y47: =+AO715+AO723+AO736 -> 0 | AE47: =+AO748+AO756+AO769 -> 0 | AK47: =+Y47*E$801 -> 0 | AQ47: =ROUND(AK47*I$815,1) -> 0
A48: =+C716 -> Segundo piso | K48: 0 | O48: 0 | U48: =+C717 -> 0 | Y48: =+AO717 -> 0 | AE48: =+AO750 -> 0 | AK48: =+Y48*E$801 -> 0 | AQ48: =ROUND(AK48*I$815,1) -> 0
A49: =+C718 -> Tercer piso | K49: 0 | O49: 0 | U49: =+C719 -> 0 | Y49: =+AO719 -> 0 | AE49: =+AO752 -> 0 | AK49: =+Y49*E$801 -> 0 | AQ49: =ROUND(AK49*I$815,1) -> 0
A50: Total área declarada en Autoavalúo | K50: 0 | O50: 0 | U50: =SUM(U47:X49) -> 0 | Y50: =ROUND(SUM(Y47:AD49),1) -> 0 | AE50: =ROUND(SUM(AE47:AJ49),1) -> 0 | AK50: =ROUND(SUM(AK47:AP49),1) -> 0 | AQ50: =ROUND(SUM(AQ47:AV49),1) -> 0
A51: Detalle de áreas NO declaradas en Partida Registral ni Autoavalúo
A52: =+C219 -> Primer piso | K52: 0 | O52: 0 | U52: =+C220 -> 0 | Y52: =+AO220+AO228+AO241 -> 0 | AE52: =+AO246+AO254+AO267 -> 0 | AK52: =+Y52*$E$452 -> 0 | AQ52: =ROUND(AK52*I$466,1) -> 0
A53: =+C221 -> Segundo piso | K53: 0 | O53: 0 | U53: =+C222 -> 0 | Y53: =+AO222 -> 0 | AE53: =+AO248 -> 0 | AK53: =+Y53*$E$452 -> 0 | AQ53: =ROUND(AK53*I$466,1) -> 0
A54: =+C223 -> Tercer piso | K54: 0 | O54: 0 | U54: =+C224 -> 0 | Y54: =+AO224 -> 0 | AE54: =+AO250 -> 0 | AK54: =+Y54*$E$452 -> 0 | AQ54: =ROUND(AK54*I$466,1) -> 0
A55: Total área NO declarada en Partida Registral ni Autoavalúo | K55: 0 | O55: 0 | U55: =SUM(U52:X54) -> 0 | Y55: =ROUND(SUM(Y52:AD54),1) -> 0 | AE55: =ROUND(SUM(AE52:AJ54),1) -> 0 | AK55: =ROUND(SUM(AK52:AP54),1) -> 0 | AQ55: =ROUND(SUM(AQ52:AV54),1) -> 0
A56: TOTALES | O56: =+O45+O50+O55 -> 0 | U56: =+U45+U50+U55 -> 0 | Y56: =+Y45+Y50+Y55 -> 0 | AE56: =+AE45+AE50+AE55 -> 0 | AK56: =+AK45+AK50+AK55 -> 0 | AQ56: =+AQ45+AQ50+AQ55 -> 0
A57: VALORES EN NUEVOS SOLES
A58: DESCRIPCIÓN | K58: Área Terreno (m²) | O58: Valor Terreno S/. | U58: Área Const. (m²) | Y58: Valor Construcción S/. | AE58: Valor Importe Asegurable S/. | AK58: Valor Comercial S/. | AQ58: Valor Realización S/.
A59: Detalle de áreas declaradas en Partida registral
A60: =+A40 -> Primer piso | K60: =+K40 -> 0 | O60: =ROUND(O40*$M$78,1) -> 0 | U60: =+U40 -> 0 | Y60: =ROUND(Y40*$M$78,1) -> 0 | AE60: =ROUND(AE40*$M$78,1) -> 0 | AK60: =ROUND(AK40*$M$78,1) -> 0 | AQ60: =ROUND(AQ40*$M$78,1) -> 0
A61: =+A41 -> Segundo piso | K61: =+K41 -> 0 | O61: =ROUND(O41*$M$78,1) -> 0 | U61: =+U41 -> 0 | Y61: =ROUND(Y41*$M$78,1) -> 0 | AE61: =ROUND(AE41*$M$78,1) -> 0 | AK61: =ROUND(AK41*$M$78,1) -> 0 | AQ61: =ROUND(AQ41*$M$78,1) -> 0
A62: =+A42 -> Tercer piso | K62: =+K42 -> 0 | O62: =ROUND(O42*$M$78,1) -> 0 | U62: =+U42 -> 0 | Y62: =ROUND(Y42*$M$78,1) -> 0 | AE62: =ROUND(AE42*$M$78,1) -> 0 | AK62: =ROUND(AK42*$M$78,1) -> 0 | AQ62: =ROUND(AQ42*$M$78,1) -> 0
A63: =+A43 -> Estacionamiento Nº.. | K63: =+K43 -> 0 | O63: =ROUND(O43*$M$78,1) -> 0 | U63: =+U43 -> 0 | Y63: =ROUND(Y43*$M$78,1) -> 0 | AE63: =ROUND(AE43*$M$78,1) -> 0 | AK63: =ROUND(AK43*$M$78,1) -> 0 | AQ63: =ROUND(AQ43*$M$78,1) -> 0
A64: =+A44 -> Depósito Nº … | K64: =+K44 -> 0 | O64: =ROUND(O44*$M$78,1) -> 0 | U64: =+U44 -> 0 | Y64: =ROUND(Y44*$M$78,1) -> 0 | AE64: =ROUND(AE44*$M$78,1) -> 0 | AK64: =ROUND(AK44*$M$78,1) -> 0 | AQ64: =ROUND(AQ44*$M$78,1) -> 0
A65: Total Declarado en Partida Registral | K65: =+K60 -> 0 | O65: =ROUND(SUM(O60:T64),1) -> 0 | U65: =SUM(U60:X64) -> 0 | Y65: =ROUND(SUM(Y60:AD64),1) -> 0 | AE65: =ROUND(SUM(AE60:AJ64),1) -> 0 | AK65: =ROUND(SUM(AK60:AP64),1) -> 0 | AQ65: =ROUND(SUM(AQ60:AV64),1) -> 0
A66: Detalle de áreas declaradas en Autoavalúo
...

Sheet FOTO
A2: =+'MEMORIA Y VAL'!AB94 -> 0 | C2: / | Q2: =+A2 -> 0 | R2: =+C2 -> / | AE2: =+Q2 -> 0 | AG2: =+R2 -> / | AU2: =+AE2 -> 0 | AV2: =+AG2 -> / | BI2: =+AU2 -> 0 | BK2: / | BY2: =+BI2 -> 0 | BZ2: =+BK2 -> / | CM2: =+BY2 -> 0 | CO2: =+BZ2 -> /
B20: 1 | I20: =1+B20 -> 2 | Q20: =1+I60 -> 7 | X20: =1+Q20 -> 8 | AF20: =1+X60 -> 13 | AM20: =1+AF20 -> 14 | AU20: =1+AM60 -> 19 | BB20: =1+AU20 -> 20 | BJ20: =1+BB60 -> 25 | BQ20: =1+BJ20 -> 26 | BY20: =1+BQ60 -> 31 | CF20: =1+BY20 -> 32 | CN20: =1+CF60 -> 37 | CU20: =1+CN20 -> 38
B40: =+I20+1 -> 3 | I40: =+B40+1 -> 4 | Q40: =+X20+1 -> 9 | X40: =+Q40+1 -> 10 | AF40: =+AM20+1 -> 15 | AM40: =+AF40+1 -> 16 | AU40: =+BB20+1 -> 21 | BB40: =+AU40+1 -> 22 | BJ40: =+BQ20+1 -> 27 | BQ40: =+BJ40+1 -> 28 | BY40: =+CF20+1 -> 33 | CF40: =+BY40+1 -> 34 | CN40: =+CU20+1 -> 39 | CU40: =+CN40+1 -> 40
B60: =+I40+1 -> 5 | I60: =+B60+1 -> 6 | Q60: =+X40+1 -> 11 | X60: =+Q60+1 -> 12 | AF60: =+AM40+1 -> 17 | AM60: =+AF60+1 -> 18 | AU60: =+BB40+1 -> 23 | BB60: =+AU60+1 -> 24 | BJ60: =+BQ40+1 -> 29 | BQ60: =+BJ60+1 -> 30 | BY60: =+CF40+1 -> 35 | CF60: =+BY60+1 -> 36 | CN60: =+CU40+1 -> 41 | CU60: =+CN60+1 -> 42
I61: =+F60+1 -> 1 | X61: =+U60+1 -> 1 | AM61: =+AJ60+1 -> 1 | BB61: =+AY60+1 -> 1 | BQ61: =+BN60+1 -> 1 | CF61: =+CC60+1 -> 1 | CU61: =+CR60+1 -> 1

Sheet SUSTENTO DE UBICACION
A2: =+FOTO!A2 -> 0 | C2: =+FOTO!C2 -> / | P2: =+A2 -> 0 | R2: =+C2 -> / | AE2: =+P2 -> 0 | AG2: =+R2 -> /
B4: PLANO BGR | Q4: PLANO DE VISOR GEOLLACTA
B32: GOOGLE EARTH CON MEDICION | Q32: PLANO ÁREA DE TERRENO

Sheet Anexo 1
A2: ANEXO N° 01
C4: CLIENTE: | D4: =+'MEMORIA Y VAL'!S97 -> 0
A6: CUADRO DE EDIFICACIÓN DE ÁREAS DECLARADAS Y NO DECLARADAS EN RR.PP.
A8: MONEDA: DOLARES AMERICANOS US$
A10: DESCRIPCIÓN | B10: Área Terreno m2 | C10: Valor Terreno US$ | D10: Área Construida m2 | E10: Valor Construcción US$ /M2 | F10: Valor Importe Asegurable US$ | G10: Depreciación | H10: Valor Comercial US$ | I10: % Valor | J10: Valor de Realización US$
B11: m2. | C11: US$ | D11: m2. | F11: US$ | H11: US$ | J11: US$
A12: Área Declarada en RRPP
A13: =+'MEMORIA Y VAL'!A40 -> Primer piso | B13: =+'MEMORIA Y VAL'!K40 -> 0 | C13: =+'MEMORIA Y VAL'!O40 -> 0 | D13: =+'MEMORIA Y VAL'!U40 -> 0 | E13: =+'MEMORIA Y VAL'!Y40 -> 0 | F13: =+'MEMORIA Y VAL'!AE40 -> 0 | G13: =+'MEMORIA Y VAL'!Z328 -> 1 | H13: =+'MEMORIA Y VAL'!AK40 -> 0 | I13: =+'MEMORIA Y VAL'!I466 -> 0.8 | J13: =+'MEMORIA Y VAL'!AQ40 -> 0
A14: =+'MEMORIA Y VAL'!A41 -> Segundo piso | D14: =+'MEMORIA Y VAL'!U41 -> 0 | E14: =+'MEMORIA Y VAL'!Y41 -> 0 | F14: =+'MEMORIA Y VAL'!AE41 -> 0 | G14: =+'MEMORIA Y VAL'!Z330 -> 1 | H14: =+'MEMORIA Y VAL'!AK41 -> 0 | I14: =+I13 -> 0.8 | J14: =+'MEMORIA Y VAL'!AQ41 -> 0
A15: =+'MEMORIA Y VAL'!A42 -> Tercer piso | D15: =+'MEMORIA Y VAL'!U42 -> 0 | E15: =+'MEMORIA Y VAL'!Y42 -> 0 | F15: =+'MEMORIA Y VAL'!AE42 -> 0 | G15: =+'MEMORIA Y VAL'!Z332 -> 1 | H15: =+'MEMORIA Y VAL'!AK42 -> 0 | I15: =+I14 -> 0.8 | J15: =+'MEMORIA Y VAL'!AQ42 -> 0
A16: =+'MEMORIA Y VAL'!A43 -> Estacionamiento Nº.. | D16: =+'MEMORIA Y VAL'!U43 -> 0 | E16: =+'MEMORIA Y VAL'!Y43 -> 0 | F16: =+'MEMORIA Y VAL'!AE43 -> 0 | H16: =+'MEMORIA Y VAL'!AK43 -> 0 | I16: =+I15 -> 0.8 | J16: =+'MEMORIA Y VAL'!AQ43 -> 0
A17: =+'MEMORIA Y VAL'!A44 -> Depósito Nº … | D17: =+'MEMORIA Y VAL'!U44 -> 0 | E17: =+'MEMORIA Y VAL'!Y44 -> 0 | F17: =+'MEMORIA Y VAL'!AE44 -> 0 | H17: =+'MEMORIA Y VAL'!AK44 -> 0 | I17: =+I16 -> 0.8 | J17: =+'MEMORIA Y VAL'!AQ44 -> 0
A18: TOTAL DECLARADO | F18: =ROUND(SUM(F13:F17),1) -> 0 | H18: =ROUND(SUM(H13:H17),1) -> 0 | J18: =ROUND(SUM(J13:J17),1) -> 0
A19: Edificación Declarada en Autovalúo
A20: =+'MEMORIA Y VAL'!A47 -> Primer piso | D20: =+'MEMORIA Y VAL'!U47 -> 0 | E20: =+'MEMORIA Y VAL'!Y47 -> 0 | F20: =+'MEMORIA Y VAL'!AE47 -> 0 | G20: =+'MEMORIA Y VAL'!AA715 -> 1 | H20: =+'MEMORIA Y VAL'!AK47 -> 0 | I20: =+I17 -> 0.8 | J20: =+'MEMORIA Y VAL'!AQ47 -> 0
A21: =+'MEMORIA Y VAL'!A48 -> Segundo piso | D21: =+'MEMORIA Y VAL'!U48 -> 0 | E21: =+'MEMORIA Y VAL'!Y48 -> 0 | F21: =+'MEMORIA Y VAL'!AE48 -> 0 | G21: =+'MEMORIA Y VAL'!AA717 -> 1 | H21: =+'MEMORIA Y VAL'!AK48 -> 0 | I21: =+I20 -> 0.8 | J21: =+'MEMORIA Y VAL'!AQ48 -> 0
A22: =+'MEMORIA Y VAL'!A49 -> Tercer piso | D22: =+'MEMORIA Y VAL'!U49 -> 0 | E22: =+'MEMORIA Y VAL'!Y49 -> 0 | F22: =+'MEMORIA Y VAL'!AE49 -> 0 | G22: =+'MEMORIA Y VAL'!AA719 -> 1 | H22: =+'MEMORIA Y VAL'!AK49 -> 0 | I22: =+I21 -> 0.8 | J22: =+'MEMORIA Y VAL'!AQ49 -> 0
A23: TOTAL DECLARADO EN PU | F23: =SUM(F20:F22) -> 0 | H23: =SUM(H20:H22) -> 0 | J23: =SUM(J20:J22) -> 0
A24: Edificacion No esta en PU ni en RRPP
A25: TOTAL ESTIMADO | F25: =+'MEMORIA Y VAL'!AE55 -> 0 | H25: =+'MEMORIA Y VAL'!AK55 -> 0 | J25: =+'MEMORIA Y VAL'!AQ55 -> 0
C27: TOTAL DECLARADO + DECLARADO EN PU + ESTIMADO | F27: =+F25+F23+F18 -> 0 | H27: =+H25+H23+H18 -> 0 | J27: =+J25+J23+J18 -> 0

Sheet Anexo 2
A2: ANEXO N° 02
C4: CLIENTE: | D4: =+'Anexo 1'!D4 -> 0
A6: CUADRO DE EDIFICACIÓN DE ÁREAS DECLARADAS Y NO DECLARADAS EN RR.PP.
A8: MONEDA: NUEVOS SOLES S/.
D10: TIPO DE CAMBIO: S/. | F10: =+[5]HR!K38 -> 3.508
A12: DESCRIPCIÓN | B12: Área Terreno m2 | C12: Valor Terreno S/ | D12: Área Construida m2 | E12: Valor Construcción S/M2 | F12: Valor Importe Asegurable S/ | G12: Depreciación | H12: Valor Comercial S/ | I12: % Valor | J12: Valor de Realización S/
B13: m2. | C13: US$ | D13: m2. | F13: US$ | H13: US$ | J13: US$
A14: Área Declarada en RRPP
A15: =+'Anexo 1'!A13 -> Primer piso | B15: =+'Anexo 1'!B13 -> 0 | C15: =+'MEMORIA Y VAL'!O60 -> 0 | D15: =+'Anexo 1'!D13 -> 0 | E15: =+'MEMORIA Y VAL'!Y60 -> 0 | F15: =+'MEMORIA Y VAL'!AE60 -> 0 | G15: =+'Anexo 1'!G13 -> 1 | H15: =+'MEMORIA Y VAL'!AK60 -> 0 | I15: =+'Anexo 1'!I13 -> 0.8 | J15: =+'MEMORIA Y VAL'!AQ60 -> 0
A16: =+'Anexo 1'!A14 -> Segundo piso | D16: =+'Anexo 1'!D14 -> 0 | E16: =+'MEMORIA Y VAL'!Y61 -> 0 | F16: =+'MEMORIA Y VAL'!AE61 -> 0 | G16: =+'Anexo 1'!G14 -> 1 | H16: =+'MEMORIA Y VAL'!AK61 -> 0 | I16: =+'Anexo 1'!I14 -> 0.8 | J16: =+'MEMORIA Y VAL'!AQ61 -> 0
A17: =+'Anexo 1'!A15 -> Tercer piso | D17: =+'Anexo 1'!D15 -> 0 | E17: =+'MEMORIA Y VAL'!Y62 -> 0 | F17: =+'MEMORIA Y VAL'!AE62 -> 0 | G17: =+'Anexo 1'!G15 -> 1 | H17: =+'MEMORIA Y VAL'!AK62 -> 0 | I17: =+'Anexo 1'!I15 -> 0.8 | J17: =+'MEMORIA Y VAL'!AQ62 -> 0
A18: =+'Anexo 1'!A16 -> Estacionamiento Nº.. | D18: =+'Anexo 1'!D16 -> 0 | E18: =+'MEMORIA Y VAL'!Y63 -> 0 | F18: =+'MEMORIA Y VAL'!AE63 -> 0 | H18: =+'MEMORIA Y VAL'!AK63 -> 0 | I18: =+'Anexo 1'!I16 -> 0.8 | J18: =+'MEMORIA Y VAL'!AQ63 -> 0
A19: =+'Anexo 1'!A17 -> Depósito Nº … | D19: =+'Anexo 1'!D17 -> 0 | E19: =+'MEMORIA Y VAL'!Y64 -> 0 | F19: =+'MEMORIA Y VAL'!AE64 -> 0 | H19: =+'MEMORIA Y VAL'!AK64 -> 0 | I19: =+'Anexo 1'!I17 -> 0.8 | J19: =+'MEMORIA Y VAL'!AQ64 -> 0
A20: TOTAL DECLARADO | F20: =ROUND(SUM(F15:F19),1) -> 0 | H20: =ROUND(SUM(H15:H19),1) -> 0 | J20: =ROUND(SUM(J15:J19),1) -> 0
A21: Edificación Declarada en Autovalúo
A22: =+'Anexo 1'!A20 -> Primer piso | D22: =+'Anexo 1'!D20 -> 0 | E22: =+'MEMORIA Y VAL'!Y67 -> 0 | F22: =+'MEMORIA Y VAL'!AE67 -> 0 | G22: =+'Anexo 1'!G20 -> 1 | H22: =+'MEMORIA Y VAL'!AK67 -> 0 | I22: =+I19 -> 0.8 | J22: =+'MEMORIA Y VAL'!AQ67 -> 0
A23: =+'Anexo 1'!A21 -> Segundo piso | D23: =+'Anexo 1'!D21 -> 0 | E23: =+'MEMORIA Y VAL'!Y68 -> 0 | F23: =+'MEMORIA Y VAL'!AE68 -> 0 | G23: =+'Anexo 1'!G21 -> 1 | H23: =+'MEMORIA Y VAL'!AK68 -> 0 | I23: =+I22 -> 0.8 | J23: =+'MEMORIA Y VAL'!AQ68 -> 0
A24: =+'Anexo 1'!A22 -> Tercer piso | D24: =+'Anexo 1'!D22 -> 0 | E24: =+'MEMORIA Y VAL'!Y69 -> 0 | F24: =+'MEMORIA Y VAL'!AE69 -> 0 | G24: =+'Anexo 1'!G22 -> 1 | H24: =+'MEMORIA Y VAL'!AK69 -> 0 | I24: =+I23 -> 0.8 | J24: =+'MEMORIA Y VAL'!AQ69 -> 0
A25: TOTAL DECLARADO EN PU | F25: =ROUND(SUM(F22:F24),1) -> 0 | H25: =ROUND(SUM(H22:H24),1) -> 0 | J25: =ROUND(SUM(J22:J24),1) -> 0
A26: Edificacion No esta en PU ni en RRPP
A27: TOTAL ESTIMADO | F27: =+'MEMORIA Y VAL'!AE75 -> 0 | H27: =+'MEMORIA Y VAL'!AK75 -> 0 | J27: =+'MEMORIA Y VAL'!AQ75 -> 0
C29: TOTAL DECLARADO + DECLARADO EN PU + ESTIMADO | F29: =+F27+F25+F20 -> 0 | H29: =+H27+H25+H20 -> 0 | J29: =+J27+J25+J20 -> 0

Sheet Anexo 3 
C3: =+'[6]Anexo 2'!D2 -> INFORME N°26 | E3: =+'MEMORIA Y VAL'!AB94 -> 0
A5: ANEXO N° 03
B7: CLIENTE: | C7: =+'Anexo 2'!D4 -> 0
A9: OFERTA INMOBILIARIA
A11: Ubicación y Descripción | B11: Distancia al Inmueble | C11: Área Terreno m2 | D11: Area Construida m2 | E11: Precio Venta US$ | F11: VUT m2 | G11: Referencia Telefonos
A12: =+'MEMORIA Y VAL'!C298 -> PONER DISTANCIAS | C12: =+'MEMORIA Y VAL'!X298 -> 0 | D12: =+'MEMORIA Y VAL'!AA298 -> 0 | E12: =+'MEMORIA Y VAL'!AD298 -> 0 | F12: =+'MEMORIA Y VAL'!AS298 -> #DIV/0! | G12: =+A12 -> PONER DISTANCIAS
A13: =+'MEMORIA Y VAL'!C300 -> 0 | C13: =+'MEMORIA Y VAL'!X300 -> 0 | D13: =+'MEMORIA Y VAL'!AA300 -> 0 | E13: =+'MEMORIA Y VAL'!AD300 -> 0 | F13: =+'MEMORIA Y VAL'!AS300 -> #DIV/0! | G13: =+A13 -> 0
A14: =+'MEMORIA Y VAL'!C302 -> 0 | C14: =+'MEMORIA Y VAL'!X302 -> 0 | D14: =+'MEMORIA Y VAL'!AA302 -> 0 | E14: =+'MEMORIA Y VAL'!AD302 -> 0 | F14: =+'MEMORIA Y VAL'!AS302 -> #DIV/0! | G14: =+A14 -> 0
A15: =+'MEMORIA Y VAL'!C304 -> "INMUEBLES VENDIDOS - VENTAS CERRADAS" Tomado del aplicativo Vanetmap | G15: =+A15 -> "INMUEBLES VENDIDOS - VENTAS CERRADAS" Tomado del aplicativo Vanetmap
A16: =+'MEMORIA Y VAL'!C305 -> 0 | C16: =+'MEMORIA Y VAL'!X305 -> 0 | D16: =+'MEMORIA Y VAL'!AA305 -> 0 | E16: =+'MEMORIA Y VAL'!AD305 -> 0 | F16: =+'MEMORIA Y VAL'!AS305 -> #DIV/0! | G16: =+A16 -> 0
A17: =+'MEMORIA Y VAL'!C416 -> 0 | D17: =+'MEMORIA Y VAL'!AA416 -> 0 | E17: =+'MEMORIA Y VAL'!AD416 -> 0 | F17: =+'MEMORIA Y VAL'!AS416 -> #DIV/0! | G17: =+A17 -> 0
A18: =+'MEMORIA Y VAL'!C418 -> 0 | D18: =+'MEMORIA Y VAL'!AA418 -> 0 | E18: =+'MEMORIA Y VAL'!AD418 -> 0 | F18: =+'MEMORIA Y VAL'!AS418 -> #DIV/0! | G18: =+A18 -> 0
A19: =+'MEMORIA Y VAL'!C420 -> "INMUEBLES VENDIDOS - VENTAS CERRADAS" Tomado del aplicativo Vanetmap | G19: =+A19 -> "INMUEBLES VENDIDOS - VENTAS CERRADAS" Tomado del aplicativo Vanetmap
A20: =+'MEMORIA Y VAL'!C421 -> 0 | D20: =+'MEMORIA Y VAL'!AA421 -> 0 | E20: =+'MEMORIA Y VAL'!AD421 -> 0 | F20: =+'MEMORIA Y VAL'!AS421 -> #DIV/0! | G20: =+A20 -> 0
A22: Conclusión:
A23: =+'MEMORIA Y VAL'!C321 -> 0
D29: =+'MEMORIA Y VAL'!V322 -> 0 | E29: / m2 | AA29: / m2

Sheet DECLARACIÓN JURADA
B5: =+'Anexo 3 '!C3 -> INFORME N°26 | D5: =+'Anexo 3 '!E3 -> 0
A7: DECLARACIÓN JURADA POR CALIDAD DE INFORME DE TASACIÓN
B9: CLIENTE: | C9: =+'Anexo 3 '!C7 -> 0
A11: Descripción | E11: INDICE* (Ubicación Pagina) | F11: Cumplimiento (Check List)
A12: Fecha de la información técnica y de los precios que está utilizando. | E12: 2-3 | F12: a
A13: Presenta tres secciones: memoria descriptiva, valuación y anexos. | E13: 3-4-5-6 | F13: a
A14: Se justifica el factor de corrección al valor comercial. | E14: 10(E.1) | F14: a
A15: Informa sobre la Zonificación y uso actual del predio. | E15: 4(B.7-5) | F15: a
A16: Evalúa la existencia de Infraestructura de servicios urbanos que afecten al predio. | E16: 4(B-8) | F16: a
A17: Detalla las características del entorno urbano. | E17: 4(B-8) | F17: a
A18: Realiza análisis de la documentación registral (RR.PP. Y Autovaluo) | E18: 4(B-6) | F18: a
A19: Determina el valor del terreno en base al valor unitario obtenido del estudio de mercado inmobiliario de la zona. | E19: 7-8 | F19: a
A20: Cuenta con REPEV vigente. | E20: 29 | F20: a
A21: Declara que no pertenece al mismo grupo económico, no tener relación laboral ni tener vínculo con los propietarios. | E21: 6(B-15) | F21: a
A22: Metodología para determinar el VC de un bien inmueble; VC=valor del terreno valor de la edificación + valor de las instalaciones fijas y obras complementarias. | E22: 7-8(C.1) | F22: a

Sheet HR
A1: HOJA RESUMEN - VALORIZACION DE INMUEBLES - SCOTIABANK
A2: DATOS GENERALES | E2: Nueva Plantilla
A3: SOLICITANTE | B3: SCOTIABANK PERU S.A.A. | E3: N° DE SOLICITUD
A4: BANCA | B4: Microempresa | E4: PRODUCTO | M4: Nombre del tasador | N4: Cod. | Q4: Tipo de Edificacion | S4: TIPO DE GARANTIA | V4: USOS DEL BIEN | X4: Materiales | Z4: Ubicación de Terreno | AB4: Ocupantes | AD4: N° Pisos
A5: FUNCIONARIO BANCO | B5: =+'MEMORIA Y VAL'!M86 -> 0 | E5: AGENCIA | H5: MONEDA | M5: Achata Arias, Oscar Emiliano | N5: 1044 | Q5: 1-Hasta 4 pisos | S5: 1 | T5: Hipoteca | V5: 1-Almacén | X5: 1-Concreto Armado | Z5: 1-Interior | AB5: 1. Inquilino precario | AD5: 0
A6: DATOS DE LA GTIA | M6: Alvarez Barrantes Julio | N6: 131 | Q6: 2-Entre 5 y 10 pisos | S6: 2 | T6: Prenda | V6: 2-Comercial | X6: 2-Ladrillo y Cemento | Z6: 2-Exterior | AB6: 2. Inquilinos | AD6: 1
A7: TIPO DE GARANTIA | B7: 1 | C7: =IF(B7="","",VLOOKUP(B7,S5:T5,2,FALSE)) -> Hipoteca | E7: SUBTIPO | H7: =IF(F7="","",VLOOKUP(F7,X21:Y43,2,FALSE)) | M7: American Tasaciones S.A.C. | N7: 2 | Q7: 3-Más de 10 pisos | V7: 3-Industrial | X7: 3-Estructura de Acero/Metálica | Z7: 3-Mediterraneo | AB7: 3. Propietario | AD7: 2
A8: DATOS DEL CLIENTE | M8: Angulo Roldan Diego | N8: 42 | Q8: 4-Nave Industrial | V8: 4-Oficina | X8: 4-Adobe/Quincha | AB8: 4. Desocupado | AD8: 3
A9: CLIENTE | B9: =+'MEMORIA Y VAL'!S97 -> 0 | E9: TELEFONOS | M9: Ara Contratistas Generales S.A.C. | N9: 1074 | Q9: 5-Otros | V9: 5-Vivienda | X9: 5-Madera | AB9: 5. Familiar | AD9: 4
A10: CTA BT | E10: DNI/RUC | M10: Arenas Callenueva, Ramón Fernando | N10: 141 | V10: 6-Terreno | X10: 7-Mampostería de Arcilla | AB10: 6. Se desconoce | AD10: 5
A11: DATOS COORD. VALORIZACION | M11: Arestegui Rodriguez Marianela | N11: 1085 | Q11: Estado de Conservación | X11: 8-Concreto Armado con Placas | Z11: Terreno Cercado | AD11: 6
A12: COORD. VALORIZACION CON: | B12: =+'MEMORIA Y VAL'!AI103 -> 0 | E12: TELEFONOS | F12: =+'MEMORIA Y VAL'!O104 -> 0 | M12: ASESORÍA VALUATORÍA S.A. | N12: 113 | Q12: Muy Bueno | X12: 9-Ladrillo y Cemento DFlex | Z12: SI | AB12: Servicios | AD12: 7
A13: Email | M13: Astete Lopez Francois | N13: 1087 | Q13: Bueno | V13: Ubicación de Terreno | X13: A-Constr Informal Albañería | Z13: NO | AB13: 1-Agua | AD13: 8
A14: DATOS DEL PERITO | M14: Avaluos E Ingenieria S.A.C | N14: 46 | Q14: Regular | V14: 1-Interior | X14: B-Estructura Industrial/Comer | AB14: 2-Luz | AD14: 9
A15: PERITO ASIGNADO | B15: Vanet S.A.C. | D15: =+VLOOKUP(B15,M5:N69,2,FALSE) -> 105 | E15: FECHA de REPEV | F15: 45865 | H15: NOMBRE del INSPECTOR | J15: Ing. Ricardo Barthelmess Saco | M15: Balarezo Flores Luis Enrique | N15: 125 | Q15: Malo | V15: 2-Exterior | X15: C-Muros Concreto Armado Duc | AB15: 3-Luz y Agua | AD15: 10
A16: DATOS DEL BIEN | M16: Bravo Hidalgo Félix Enrique | N16: 34 | Q16: En construcción | AB16: 4-Desague | AD16: 11
A17: N° PARTIDA | B17: =+'MEMORIA Y VAL'!$AC$148 -> 0 | F17: FECHA INSPECCIÓN | H17: =+'MEMORIA Y VAL'!U103 -> 0 | I17: FECHA EXPEDICIÓN | K17: =+'MEMORIA Y VAL'!V99 -> 0 | M17: Bravo Puccio Emilio | N17: 104 | AB17: 5-Todos | AD17: 12
A18: PROPIETARIO | B18: =+'MEMORIA Y VAL'!$S$98 -> 0 | M18: Castillo Alzamora Pedro | N18: 1065 | Q18: Tipo de Acabados | AD18: 13
A19: UBICACIÓN DEL BIEN | B19: =+'MEMORIA Y VAL'!$C$111 -> 0 | M19: CENTRA VALUACIONES SAC | N19: 26 | Q19: Primera | AD19: 14
A20: REFERENCIAS DE UBICACIÓN | M20: Cesar Arroyo Burga S.R.L. | N20: 1063 | Q20: Segunda | V20: ZONIFICACIÓN | X20: SUBTIPO | AD20: 15
A21: DEPARTAMENTO | E21: PROVINCIA | I21: DISTRITO | M21: Cesar Luis Reyes Cano | N21: 1077 | Q21: N/A | V21: 1-RDA (zona de densidad alta) | X21: TERRENO URBANO (sin valor asegurable) | Y21: 40 | AD21: 16
A22: ZONIFICACIÓN | E22: UBIGEO | F22: =IF(J21="","",VLOOKUP(J21,Limites2015!J1:K1875,2,FALSE)) | G22: Latitud | H22: =+'MEMORIA Y VAL'!$U$34 -> 0 | I22: Longitud | J22: =+'MEMORIA Y VAL'!$AK$34 -> 0 | M22: Cieza Paredes Antonio | N22: 130 | V22: 2-RDM (zona de densidad media) | X22: TERRENO RUSTICO (sin valor asegurable) | Y22: 50 | AD22: 17
A23: TIPO TERRENO | C23: Terreno Cercado | E23: Ubicación de Terreno | G23: Servicios | M23: Clavijo Coronado Roger | N23: 1072 | V23: 3-RDB (zona de densidad baja) | X23: Horizontal BIEN TERMINADO-DEPARTAMENTO | Y23: 22 | AD23: 20
A24: USOS DEL BIEN | C24: % de uso del bien | E24: N° Pisos | G24: N° Sotanos | I24: Año de construccion | K24: =2026-'MEMORIA Y VAL'!$M$207 -> 2026 | M24: Constructora Piedra Angular S.A.C. | N24: 25 | Q24: TIPO TERRENO | V24: 4-I1R (vivienda-taller) | X24: Horizontal BIEN TERMINADO-OFICINA | Y24: 23 | AD24: 25
A25: Tipo de Edificacion | C25: N° Deposito | E25: N° Estacionamto | G25: Materiales | J25: Ocupantes | M25: Consultora Y Constructora "Fisavi" S.A.C. | N25: 143 | Q25: Terreno Urbano | V25: 5-I (industgrial) | X25: Horizontal BIEN TERMINADO-LOCAL COMERCIAL | Y25: 28 | AD25: 26
A26: ESPECIFICACIONES GENERALES - TERRENO AGRICOLA | M26: Cynthia Ochoa Pino | N26: 1078 | Q26: Terreno Rustico | V26: 6-I4 (zona industrial pesada) | X26: BIEN TERMINADO-CASA HABITACION | Y26: 21 | AD26: 27
A27: AMENAZAS | E27: Cultivos y Variedades | M27: Dante Alex Vega Aranda | N27: 17 | Q27: Terreno Agricola | V27: 7-I3 (zona de gran industria) | X27: BIEN FUTURO-CASA HABITACION | Y27: 15 | AD27: 28
A28: Area total del terreno (ha) | E28: Area sembrada (ha) | M28: Diaz Villacorta Carlos Ricardo | N28: 37 | V28: 8-I2 (zona de industgria mediana) | X28: Horizontal BIEN FUTURO-DEPARTAMENTO | Y28: 16 | AD28: 29
A29: CUENTA CON LICENCIAS DE AGUA | C29: Vigencia de Licencia | E29: Caudal total (lt/sg) | M29: Estudio Jalvo S.A.C | N29: 45 | Q29: BANCA | V29: 9-I1 (zona industrial elemental) | X29: Horizontal BIEN FUTURO-OFICINA | Y29: 17 | AD29: 30
A30: CON AGUA SUPERFICIAL | E30: Caudal (lt/sg) | M30: Flores Herrera Javier | N30: 1045 | Q30: Adjudicados | V30: 10- C (comercial) | X30: UNIVERSIDAD | Y30: 24 | AD30: 31
A31: CON POZOS | B31: N° de Pozos | E31: Caudal (lt/sg) | G31: Ubicación de Pozos | M31: Giancarlo Martino Herrera | N31: 21 | Q31: Banca Empresa | V31: 11-CE (zona de comercio especializado) | X31: INSTITUTO | Y31: 25 | AD31: 32
A32: DOCUMENTOS SUSTENTATORIOS | M32: Grupo Vargo Sac | N32: 38 | Q32: Banca Personal | V32: 12-CM (zona de comercio metropolitano) | X32: MALL | Y32: 26 | AD32: 33
A33: COPIA LITERAL | D33: PLANO DE UBICACIÓN | G33: HR - PU | M33: Guibovich Jose | N33: 1018 | Q33: Bca. Especial | V33: 13-CZ (zona de comercio zonal) | X33: PREDIO AGRICOLA | Y33: 27 | AD33: 34
A34: LICENCIAS DE USO DE AGUA: | D34: SERVIDUMBRES DE PASO TERRENO | M34: Ingenieria Maxima Eirl- Imax | N34: 4 | Q34: Microempresa | V34: 14-CV (zona de comercio vecinal) | X34: Exclusivo LOCAL COMERCIAL | Y34: 14 | AD34: 35
A35: SUPERFICIAL | D35: MEMORIA DESCRIPTIVA | G35: CERTIFICADO DE PARAMETROS / LICENCIA DE EDIFICACION | M35: Inversiones Trica Sac | N35: 44 | Q35: SCI | X35: AERONAVES | Y35: 30 | AD35: 36
A36: SUBTERRANEA | D36: MINUTA COMPRA VENTA | G36: SERVIDUMBRES DE PASO DE TERRENO DE UBICACIÓN DE POZOS A CAMPOS | M36: J & E Mesias Consultores S.A.C. | N36: 36 | Q36: Wholesale Banking | X36: TALLER | Y36: 3
A37: VALORES UNITARIOS M2 | M37: Jl Viterri Ingenieros S.A.C. | N37: 7 | X37: COLEGIO | Y37: 7
A38: VALOR TERRENO X M2 | B38: =+'MEMORIA Y VAL'!$V$322 -> 0 | C38: AREA DE TERRENO TOTAL m2 | D38: =+'MEMORIA Y VAL'!$AO$130 -> 0 | E38: AREA DE TECHADA TOTAL m2 | F38: =+'MEMORIA Y VAL'!N182 -> 0 | G38: VALOR AREA UTIL VENDIBLE X m2 del inmueble | I38: =+'MEMORIA Y VAL'!$AK$56/'MEMORIA Y VAL'!$U$56 -> #DIV/0! | J38: TIPO CAMBIO: | K38: =+'MEMORIA Y VAL'!$M$78 -> 3.495 | M38: Jrb Consultores Sac | N38: 53 | X38: CENTRO DE SALUD | Y38: 8
A39: VALORIZACIÓN | M39: Jrz Valuaciones | N39: 8 | X39: MINA | Y39: 9
A40: Concepto (Declarado en RRPP) | B40: m2 | C40: Tipo de Acabados | D40: Estado de Conservación | E40: Año de Construc. | F40: Moneda / m2 | G40: Factor Deprec. | H40: Valor Asegurable | I40: Valor Comercial | J40: % Valor | K40: Valor Realización | M40: Juan Enrique Naveda Sarmiento | N40: 115 | X40: ALMACENES - DEPOSITOS | Y40: 10
...

Sheet Limites2015
A1: IDDIST | B1: NOMBDEP | D1: NOMBPROV | F1: NOMBDIST | H1: NOM_CAPITAL (LEGAL) | J1: NOMBDIST | K1: IDDIST
A2: 010101 | B2: AMAZONAS | D2: ABANCAY | F2: ABANCAY | H2: ABANCAY | J2: CHACHAPOYAS | K2: 010101
A3: 010102 | B3: ANCASH | D3: ACOBAMBA | F3: ABELARDO PARDO LEZAMETA | H3: LLACLLA | J3: ASUNCION | K3: 010102
A4: 010103 | B4: APURIMAC | D4: ACOMAYO | F4: ACARI | H4: ACARI | J4: BALSAS | K4: 010103
A5: 010104 | B5: AREQUIPA | D5: AIJA | F5: ACAS | H5: ACAS | J5: CHETO | K5: 010104
A6: 010105 | B6: AYACUCHO | D6: ALTO AMAZONAS | F6: ACCHA | H6: ACCHA | J6: CHILIQUIN | K6: 010105
A7: 010106 | B7: CAJAMARCA | D7: AMBO | F7: ACCOMARCA | H7: ACCOMARCA | J7: CHUQUIBAMBA | K7: 010106
A8: 010107 | B8: CALLAO | D8: ANDAHUAYLAS | F8: ACHAYA | H8: ACHAYA | J8: GRANADA | K8: 010107
A9: 010108 | B9: CUSCO | D9: ANGARAES | F9: ACHOMA | H9: ACHOMA | J9: HUANCAS | K9: 010108
A10: 010109 | B10: HUANCAVELICA | D10: ANTA | F10: ACO | H10: ACO | J10: LA JALCA | K10: 010109
A11: 010110 | B11: HUANUCO | D11: ANTABAMBA | F11: ACO | H11: ACO | J11: LEIMEBAMBA | K11: 010110
A12: 010111 | B12: ICA | D12: ANTONIO RAYMONDI | F12: ACOBAMBA | H12: ACOBAMBA | J12: LEVANTO | K12: 010111
... A26: 010204 | B26: UCAYALI | D26: CAJABAMBA | F26: ACOSTAMBO | H26: ACOSTAMBO | J26: EL PARCO | K26: 010204
A27: 010205 | D27: CAJAMARCA | F27: ACRAQUIA | H27: ACRAQUIA | J27: IMAZA | K27: 010205
A28: 010206 | D28: CAJATAMBO | F28: ACZO | H28: ACZO | J28: LA PECA | K28: 010206
A29: 010301 | D29: CALCA | F29: AGALLPAMPA | H29: AGALLPAMPA | J29: JUMBILLA | K29: 010301
A30: 010302 | D30: CALLAO | F30: AGUA BLANCA | H30: AGUA BLANCA | J30: CHISQUILLA | K30: 010302
A31: 010303 | D31: CAMANA | F31: AGUAS VERDES | H31: AGUAS VERDES | J31: CHURUJA | K31: 010303
A32: 010304 | D32: CANAS | F32: AHUAC | H32: AHUAC | J32: COROSHA | K32: 010304
A33: 010305 | D33: CANCHIS | F33: AHUAYCHA | H33: AHUAYCHA | J33: CUISPES | K33: 010305
A34: 010306 | D34: CANDARAVE | F34: AIJA | H34: AIJA | J34: FLORIDA | K34: 010306
A35: 010307 | D35: CANGALLO | F35: AJOYANI | H35: AJOYANI | J35: JAZAN | K35: 010307
A36: 010308 | D36: CANTA | F36: ALBERTO LEVEAU | H36: UTCURARCA | J36: RECTA | K36: 010308
A37: 010309 | D37: CAÑETE | F37: ALCA | H37: ALCA | J37: SAN CARLOS | K37: 010309
A38: 010310 | D38: CARABAYA | F38: ALCAMENCA | H38: ALCAMENCA | J38: SHIPASBAMBA | K38: 010310
... A197: 021408 | D197: ZARUMILLA | F197: CALLAYUC | H197: CALLAYUC | J197: SAN CRISTOBAL DE RAJAN | K197: 021408
A198: 021409 | F198: CALLERIA | H198: PUCALLPA | J198: SAN PEDRO | K198: 021409
A199: 021410 | F199: CALQUIS | H199: CALQUIS | J199: SANTIAGO DE CHILCAS | K199: 021410
A200: 021501 | F200: CALZADA | H200: CALZADA | J200: CABANA | K200: 021501
A201: 021502 | F201: CAMANA | H201: CAMANA | J201: BOLOGNESI | K201: 021502
A202: 021503 | F202: CAMANTI | H202: QUINCE MIL | J202: CONCHUCOS | K202: 021503
A203: 021504 | F203: CAMILACA | H203: ALTO CAMILACA | J203: HUACASCHUQUE | K203: 021504
A204: 021505 | F204: CAMINACA | H204: CAMINACA | J204: HUANDOVAL | K204: 021505
A205: 021506 | F205: CAMPANILLA | H205: CAMPANILLA | J205: LACABAMBA | K205: 021506
A206: 021507 | F206: CAMPORREDONDO | H206: CAMPORREDONDO | J206: LLAPO | K206: 021507
A207: 021508 | F207: CAMPOVERDE | H207: CAMPO VERDE | J207: PALLASCA | K207: 021508
A208: 021509 | F208: CANARIA | H208: CANARIA | J208: PAMPAS | K208: 021509
A209: 021510 | F209: CANAYRE | H209: CANAYRE | J209: SANTA ROSA | K209: 021510
... A1875: 250401 | F1875: ZURITE | H1875: ZURITE | J1875: PURUS | K1875: 250401

Sheet DPTOS
A1: NOMBDEP | B1: NOMBPROV | C1: NOMBDIST
A2: AMAZONAS | B2: BAGUA | C2: ARAMANGO
A3: ANCASH | B3: BONGARA | C3: BAGUA
A4: APURIMAC | B4: CHACHAPOYAS | C4: COPALLIN
A5: AREQUIPA | B5: CONDORCANQUI | C5: EL PARCO
A6: AYACUCHO | B6: LUYA | C6: IMAZA
A7: CAJAMARCA | B7: RODRIGUEZ_DE_MENDOZA | C7: LA PECA
A8: CALLAO | B8: UTCUBAMBA | C8: CHISQUILLA
A9: CUSCO | B9: AIJA | C9: CHURUJA
A10: HUANCAVELICA | B10: ANTONIO_RAYMONDI | C10: COROSHA
A11: HUANUCO | B11: ASUNCION | C11: CUISPES
A12: ICA | B12: BOLOGNESI | C12: FLORIDA
... A26: UCAYALI | B26: SANTA | C26: GRANADA
B27: SIHUAS | C27: HUANCAS
B28: YUNGAY | C28: LA JALCA
B29: ABANCAY | C29: LEIMEBAMBA
B30: ANDAHUAYLAS | C30: LEVANTO
B31: ANTABAMBA | C31: MAGDALENA
B32: AYMARAES | C32: MARISCAL CASTILLA
B33: CHINCHEROS | C33: MOLINOPAMPA
B34: COTABAMBAS | C34: MONTEVIDEO
B35: GRAU | C35: OLLEROS
B36: AREQUIPA. | C36: QUINJALCA
B37: CAMANA | C37: SAN FRANCISCO DE DAGUAS
B38: CARAVELI | C38: SAN ISIDRO DE MAINO
... B197: PURUS | C197: SAN CRISTOBAL DE RAJAN
C198: SAN PEDRO
C199: SANTIAGO DE CHILCAS
C200: BOLOGNESI
C201: CABANA
C202: CONCHUCOS
C203: HUACASCHUQUE
C204: HUANDOVAL
C205: LACABAMBA
C206: LLAPO
C207: PALLASCA
C208: PAMPAS
C209: SANTA ROSA
... C1875: PURUS
