Workbook
Name ABANCAY: #REF!
Name ACOBAMBA: #REF!
Name ACOMAYO: #REF!
Name AIJA: #REF!
Name ALTO_AMAZONAS: #REF!
Name AMAZONAS: #REF!
Name AMBO: #REF!
Name ANCASH: #REF!
Name ANDAHUAYLAS: #REF!
Name ANGARAES: #REF!
Name ANTA: #REF!
Name ANTABAMBA: #REF!
Name ANTONIO_RAIMONDI: #REF!
Name APURIMAC: #REF!
Name ÁreaTechada: '[1]MD Áreas'!$K$43
Name ÁreaTerreno: '[1]MD Áreas'!$S$33
Name AREQUIPA: #REF!
Name ASCOPE: #REF!
Name ASUNCION: #REF!
Name ATALAYA: #REF!
Name AYABACA: #REF!
Name AYACUCHO: #REF!
Name AYMARAES: #REF!
Name AZANGARO: #REF!
Name BAGUA: #REF!
Name BARRANCA: #REF!
Name BELLAVISTA: #REF!
Name BOLIVAR: #REF!
Name BOLOGNESI: #REF!
Name BONGARA: #REF!
Name CAJABAMBA: #REF!
Name CAJAMARCA: #REF!
Name CAJATAMBO: #REF!
Name CALCA: #REF!
Name CALLAO: #REF!
Name CAMANA: #REF!
Name CANAS: #REF!
Name CANCHIS: #REF!
Name CANDARAVE: #REF!
Name CANGALLO: #REF!
Name CANTA: #REF!
Name CAÑETE: #REF!
Name CARABAYA: #REF!
Name CARAVELI: #REF!
Name CARHUAZ: #REF!
Name CARLOS_FERMIN_FITZCARRALD: #REF!
Name CASMA: #REF!
Name CASTILLA: #REF!
Name CASTROVIRREYNA: #REF!
Name CAYLLOMA: #REF!
Name CELENDIN: #REF!
Name CHACHAPOYAS: #REF!
Name CHANCHAMAYO: #REF!
Name CHEPEN: #REF!
Name CHICLAYO: #REF!
Name CHINCHA: #REF!
Name CHINCHEROS: #REF!
Name CHOTA: #REF!
Name CHUCUITO: #REF!
Name CHUMBIVILCAS: #REF!

Sheet Formato (HR)
A1: REGISTRO DE TASACIÓN - JANUS v1.0
A5: Tipo de Unidad | B5: Direccion Registral | D5: # de Partida
A6: =+MEMORIA!A40 -> Departamento N° | B6: =+MEMORIA!P16 -> 0
A7: =+MEMORIA!A41 -> Estacionamiento N°
A8: =+MEMORIA!A42 -> Depósito N°
A13: Datos del Informe
A15: Propietario | B15: =+MEMORIA!$C$69 -> 0
A17: Fecha de Inspección | B17: =+MEMORIA!$P$19 -> 0 | D17: Fecha de Tasación | E17: =+MEMORIA!$P$61 -> 0
A18: Hora de Inspección
A19: Tipo de Tasación | B19: MiVivienda | D19: Moneda | E19: Dólares USA-US$
A21: Año de Construcción | B21: =2026-MEMORIA!R166 -> 2026 | D21: Material de Construcción
A23: Tipo de Edificación | D23: Uso
D24: % de uso Casa Habitacion
A25: Depreciación | B25: =+MEMORIA!R166 -> 0 | D25: Ubicación | E25: Zona Residencial
A27: Estado Inmueble | C27: Ver criterios y pesos | D27: Cuenta con Fabrica
A29: Nro. de Pisos | D29: Comentarios
D30: =+MEMORIA!$C$188 -> 0
A31: Nro. de Sótanos
A33: Ubigeo | B33: =+MEMORIA!P20 -> 1501….
A35: Inquilinos | B35: No | D35: ¿Giro de Negocio Excluyente? | E35: No
A36: Alquiler inscrito en RP | B36: No
A38: Areas y Valores
A40: Área de Terreno | B40: =+MEMORIA!I43 -> 0 | D40: Área de Construcción | E40: =+MEMORIA!R43 -> 0
A42: Valor del Terreno | B42: =+MEMORIA!L43 -> 0 | D42: Valor de Construcción | E42: =+MEMORIA!Y43 -> 0
A44: Valor Casco Habitable | B44: =+MEMORIA!AQ333+MEMORIA!AQ334+MEMORIA!AQ335+MEMORIA!AQ336+MEMORIA!AQ337+MEMORIA!AQ338 -> 0 | D44: Valor de Construcción/m2 | E44: =+MEMORIA!AM162 -> 0
A46: Valor Comercial | B46: =+MEMORIA!AK43 -> 0 | D46: Valor del Estacionamiento | E46: =+MEMORIA!AK41 -> 0
A48: Valor de Realización | B48: =+MEMORIA!AQ43 -> 0 | D48: Importe Asegurable | E48: =+MEMORIA!AE43 -> 0
A50: Valor del Terreno/m2 | B50: =+MEMORIA!V235 -> 0 | D50: Monto de Tasación Proyectada | E50: =+B48 -> 0

Sheet MEMORIA
R10: =+R63 -> INFORME N° 26 | AB10: =+AB63 -> 0
A11: =+A64 -> "VALUACIÓN COMERCIAL DE INMUEBLE - MIVIVIENDA"
A12: REFERENCIA | O12: : | P12: =+C67 -> DEPARTAMENTO, ESTACIONAMIENTO Y DEPÓSITO EN EDIFICIO MULTIFAMILIAR.
A13: CLIENTE | O13: :
A14: SOLICITANTE | O14: : | P14: BANCO INTERNACIONAL DEL PERU - INTERBANK - Centro hipotecario
A15: PROPIETARIO | O15: : | P15: =+C69 -> 0
A16: Ubicación | G16: =+C71 -> Dirección Registral: | O16: : | P16: =+C72 -> 0
G17: =+C73 -> Dirección Autoavalúo: | O17: : | P17: =+C74 -> 0
G18: =+C75 -> Dirección In-Situ: | O18: : | P18: =+C76 -> 0
A19: FECHA DE INSPECCIÓN | O19: :
A20: UBIGEO: | O20: : | P20: 1501….
A21: PLANO | Z21: FACHADA
A36: COORDENADAS (Según Google Maps) | O36: : | P36: Latitud | AF36: Longitud
A37: VALORES EN DÓLARES AMERICANOS
A39: DESCRIPCIÓN | I39: Área Terr. (m²) | L39: Valor Terreno US$ | R39: Área Const. (m²) | V39: Área Ocup. (m²) | Y39: Valor Edificación US$ | AE39: Importe Asegurable US$ | AK39: Valor Comercial US$ | AQ39: Valor Realización US$
A40: =+C240 -> Departamento N° | I40: =+Y104 -> 0 | L40: =+AF240 -> 0 | R40: =+U142 -> 0 | V40: =+AB142 -> 0 | Y40: =+S301 -> 0 | AE40: =+AL301 -> 0 | AK40: =+AL301 -> 0 | AQ40: =+Z310 -> 0
A41: =+C241 -> Estacionamiento N° | I41: =+Y105 -> 0 | L41: =+AF241 -> 0 | R41: =+U143 -> 0 | V41: =+AB143 -> 0 | Y41: =+S302 -> 0 | AE41: =+AL302 -> 0 | AK41: =+AL302 -> 0 | AQ41: =+Z311 -> 0
A42: =+C242 -> Depósito N° | I42: =+Y106 -> 0 | L42: =+AF242 -> 0 | R42: =+U144 -> 0 | V42: =+AB144 -> 0 | Y42: =+S303 -> 0 | AE42: =+AL303 -> 0 | AK42: =+AL303 -> 0 | AQ42: =+Z312 -> 0
A43: TOTALES | I43: =SUM(I40:K42) -> 0 | L43: =SUM(L40:Q42) -> 0 | R43: =SUM(R40:U42) -> 0 | V43: =SUM(V40:X42) -> 0 | Y43: =SUM(Y40:AD42) -> 0 | AE43: =SUM(AE40:AJ42) -> 0 | AK43: =SUM(AK40:AP42) -> 0 | AQ43: =SUM(AQ40:AV42) -> 0
A44: VALORES EN NUEVOS SOLES
A46: DESCRIPCIÓN | I46: Área Terr. (m²) | L46: Valor Terreno S/. | R46: =+R39 -> Área Const. (m²) | V46: =+V39 -> Área Ocup. (m²) | Y46: Valor Edificación S/. | AE46: Importe Asegurable S/. | AK46: Valor Comercial S/. | AQ46: Valor Realización S/.
A47: =+A40 -> Departamento N° | I47: =+I40 -> 0 | L47: =+AF368 -> 0 | R47: =+R40 -> 0 | V47: =+V40 -> 0 | Y47: =+S400 -> 0 | AE47: =+AL400 -> 0 | AK47: =+AL400 -> 0 | AQ47: =+Z409 -> 0
A48: =+A41 -> Estacionamiento N° | I48: =+I41 -> 0 | L48: =+AF369 -> 0 | R48: =+R41 -> 0 | V48: =+V41 -> 0 | Y48: =+S401 -> 0 | AE48: =+AL401 -> 0 | AK48: =+AL401 -> 0 | AQ48: =+Z410 -> 0
A49: =+A42 -> Depósito N° | I49: =+I42 -> 0 | L49: =+AF370 -> 0 | R49: =+R42 -> 0 | V49: =+V42 -> 0 | Y49: =+S402 -> 0 | AE49: =+AL402 -> 0 | AK49: =+AL402 -> 0 | AQ49: =+Z411 -> 0
A50: TOTALES | I50: =SUM(I47:K49) -> 0 | L50: =+AF371 -> 0 | R50: =SUM(R47:U49) -> 0 | V50: =SUM(V47:X49) -> 0 | Y50: =+AQ381 -> 0 | AE50: =SUM(AE47:AJ49) -> 0 | AK50: =+AL403 -> 0 | AQ50: =+Z412 -> 0
A51: Tipo de Cambio | K51: : | M51: 3.49 | R51: /Dólar
A52: Observaciones | K52: : | M52: =+C188 -> 0
A53: Año de construcción | K53: : | M53: =2025-R166 -> 2025
A54: Material de construcción | K54: :
A55: Tipo | K55: :
A56: Ocupación y Usos | K56: : | M56: =+C78 -> 0
A57: Número de pisos | K57: :
A58: Número de sótanos | K58: :
A59: Perito Responsable | K59: : | M59: VANET SAC - REPEV SBS Nº 561-2001
A60: Funcionario | K60: :
A61: Fecha Informe | K61: : | M61: Lima ,
A62: Control Interno | K62: : | M62: / / JT
R63: INFORME N° 26
A64: "VALUACIÓN COMERCIAL DE INMUEBLE - MIVIVIENDA"
A66: 1.- | C66: CLASE DE BIEN
...

Sheet C2
E14: HOJA RESUMEN TASACIÓN DE INMUEBLES - FONDO MIVIVIENDA S.A. - C.02
A16: FECHA DE VALUACIÓN | I16: DE | T16: DE | V16: 2026
A18: ENTIDAD FINANCIERA | G18: BANCO INTERNACIONAL DEL PERU - INTERBANK | Z18: PROPIETARIO | AA18: =+MEMORIA!P15 -> 0
A20: BENEFICIARIO | G20: =+MEMORIA!P13 -> 0 | AE20: DNI / LE / CIP / CE
A22: PERITO TASADOR | G22: VANET S.A.C. | AF22: REPEV. SBS | AK22: 561 2001
A24: UBICACIÓN DEL INMUEBLE | G24: Carrt. | I24: Av. | K24: Jr. | M24: Calle | O24: Psje | S24: =+MEMORIA!C72 -> 0
A26: N° / Mza./Lt | F26: Dpto./Int. | N26: Urb./Loc
A28: Departamento | M28: Provincia | Z28: Distrito
A30: CLASIFICACIÓN | F30: BIEN FUTURO | M30: a) En Proyecto | T30: b) En Construcción | AC30: c) En acabados | AL30: d) Culminado
G31: *Bien futuro: inmueble en proyecto, en construcción o en acabados sin declaratoria de fábrica inscrita en RR.PP.
F32: BIEN TERMINADO | M32: Registro: RPI | T32: RPU | W32: Zona | AA32: Ficha | AF32: Partida | AL32: N°
F33: *Bien terminado: Inmueble con construcción terminada, con declaratoria de fábrica y de ser el caso independización inscritas en los RR.PP.
A35: DESCRIPCIÓN DEL INMUEBLE
A37: TIPO DE INMUEBLE | L37: CASA | W37: DEPARTAMENTO | AD37: Si vive en un departamento, indicar el piso
A39: AREAS | P39: AREA DEL TERRENO | R39: =+MEMORIA!I40 -> 0 | U39: M2 | AG39: AREA CONSTRUIDA | AL39: =+MEMORIA!R40 -> 0 | AO39: M2
A42: ESTADO DE CONSERVACIÓN | J42: Bueno | O42: Regular | S42: Malo | AA42: ANTIGÜEDAD CONSTRUCCIÓN | AL42: =2026-MEMORIA!R166 -> 2026 | AO42: años
A46: Sala-Comedor | F46: SI | H46: NO | L46: Dormitorios (Cantidad) | Y46: Cochera (Cantidad) | AH46: 0
A47: Cocina | F47: SI | H47: NO | L47: Dormitorio de Servicio | S47: SI | U47: NO | Y47: Jardín | AF47: SI | AJ47: NO
A48: Baños (Cantidad) | L48: Cuarto de Estudio | S48: SI | U48: NO | Y48: Terraza | AF48: SI | AJ48: NO
A49: Baño de Servicio | F49: SI | H49: NO | L49: Lavandería | S49: SI | U49: NO | Y49: Parque de uso común | AF49: SI | AJ49: NO
L50: Instalaciones de gas natural | S50: SI | U50: NO | Y50: Sala común | AF50: SI | AJ50: NO
Y51: Canchas/Gimnasios | AF51: SI | AJ51: NO
Y52: Piscina común | AF52: SI | AJ52: NO
A55: ESPECIFICACIONES TECNICAS
A57: ESTRUCTURAS
A58: CIMENTACIÓN | J58: COLUMNAS | Q58: VIGAS | X58: TECHOS | AE58: MUROS
A59: Platea de cimentación | J59: a) Concreto | Q59: a) Concreto | X59: Aligerado | AE59: Concreto | AM59: Tipos de albañilería
A60: Cimientos corridos | J60: b) Acero | Q60: b) Acero | X60: Maciso | AE60: Albañilería | AK60: Arcilla | AO60: Concreto
A61: Viga de cimentación | J61: a) y b) | Q61: a) y b) | AK61: Calcáreo | AO61: Adobe
A63: ACABADOS
B66: PUERTAS | E66: TIPO | I66: a) Apanelada | O66: b) Maciza | T66: c) Contraplacada | AB66: VENTANAS | AH66: Madera | AL66: Aluminio
E67: MATERIAL | I67: a) Fierro | O67: b) Madera | R67: X | T67: c) Otros | AH67: Fierro | AL67: Otros
A70: MUEBLES DE COCINA | AB70: APARATOS SANITARIOS
A71: AMOBLADA | J71: NO AMOBLADA | AF71: BLANCO | AK71: COLOR
A74: PISOS
B75: AMBIENTE | H75: Vinílico | M75: Parquet | R75: Machimbrado | W75: Cemento | AB75: Cerámica | AH75: Otro
B76: Sala-Comedor | AH76: X
B77: Baños | AB77: X
B78: Dormitorios | AH78: X
A80: PRECIOS REFERENCIALES
...

Sheet FOTO
A2: =+MEMORIA!$AB$63 -> 0 | C2: / … | P2: =+A2 -> 0 | R2: =+C2 -> / …
B18: 1 | H18: 2 | P18: 9 | W18: =1+P18 -> 10
B34: 3 | H34: 4 | P34: =1+W18 -> 11 | W34: =1+P34 -> 12
B51: 5 | H51: 6 | P51: =1+W34 -> 13 | W51: =1+P51 -> 14
B67: 7 | H67: 8 | P67: =1+W51 -> 15 | W67: =1+P67 -> 16

Sheet SUSTENTO DE UBICACION
A2: =+FOTO!A2 -> 0 | C2: =+FOTO!C2 -> / … | O2: =+A2 -> 0 | Q2: =+C2 -> / …
B4: PLANO BGR | P4: PLANO DE VISOR GEOLLACTA
B34: GOOGLE EARTH CON MEDICION | P34: PLANO ÁREA DE TERRENO

Sheet Lista desplegable
A4: Tipo de Tasación | B4: Moneda | C4: Material de construccion | D4: Tipo de Edificacion | E4: Uso | F4: Ubicación | G4: Estado de inmueble | H4: Tipo de Unidad | I4: Fabrica | J4: % casa habitacion | K4: Tipo de Vivienda | L4: Inquilinos | M4: Giro de Negocio Excluyente
A5: Hipotecario | B5: Dólares USA-US$ | C5: Adobe | D5: CASA HABITACION | E5: CASA HABITACION | F5: Zona Residencial | G5: Muy Bueno | H5: Departamento | I5: Si | J5: 0.1 | K5: Hipotecario | L5: Sí | M5: Si
A6: Mivivienda | B6: Soles-S/ | C6: Concreto Armado | D6: CASA HABITACION/COME | E6: CASA HABITACION/COME | F6: Zona Comercial | G6: Bueno | H6: Estacionamiento | I6: No | J6: 0.2 | K6: MiVivienda | L6: No | M6: No
C7: Drywall | D7: COMERCIAL | E7: CASA HABITACION/INDU | F7: Zona Mixta | G7: Regular | H7: Deposito | I7: Parcial | J7: 0.3
C8: Estructura de Acero/Metálica | D8: COMERCIAL/INDUSTRIAL | E8: COMERCIAL | G8: Malo | H8: Aires | J8: 0.4
C9: Estructura metálica con planchas industriales | D9: EDIFICIO | E9: INDUSTRIAL | G9: Muy Malo | H9: Casa Habitacion | J9: 0.5
C10: Ladrillo y Cemento | D10: ESTACIONAMIENTO | E10: OTROS | H10: Duplex | J10: 0.6
C11: Madera | D11: INDUSTRIAL | E11: TERRENO USO RESIDENCIAL | H11: Local Comercial | J11: 0.7
C12: Planchas colaborantes | D12: OTROS | H12: Oficina | J12: 0.8
C13: Quincha | D13: TIENDA DEPOSITO | H13: Palco | J13: 0.9
D14: TERRENO | H14: Terreno | J14: 1
H15: Departamento Duplex
H16: Departamento Triplex
H17: Estacionamiento doble
H18: Estacionamiento triple
H19: Estacionamiento con deposito
H20: Estacionamiento bicicleta
H21: Closet

Sheet Criterio y peso estado inmueble
B3: Si se encuentra un inmueble en mal estado, por favor, especificar en el comentario la recomendación de considerar solo el valor del terreno.
B5: Criterio | C5: Porcentajes | D5: Explicación | E5: Ejemplo
B6: Estructuras | C6: 0.4 | D6: Lo que concierne a muros y columnas. Es decir, si el inmueble tiene fisuras graves (estructurales) o leves (que se solucionan con un tarrajeo). El número de fisuras está en función a cada inmueble. | E6: Fisuras graves lo que concierne a la estructura del predio en sí, ponen en riesgo al inmueble.
B7: Techos | C7: 0.1 | D7: Lo que concierto al estado de los techos. Por ejemplo, grietas, etc. | E7: Si un inmueble aún no tiene techo o el techo se encuentra en ´malas condiciones.
B8: Revestimiento | C8: 0.1 | D8: Lo que concierne al revestimiento del inmueble, como pintura, etc. | E8: Si un inmueble aún se encuentra en ladrillo, quedando pendiente el tarrajeo y pintura.
B9: Instalaciones | C9: 0.1 | D9: Lo que concierne a las instalaciones de agua, luz, saneamiento. | E9: Contar con acceso a agua y luz ya instaladas en el predio-
B10: Puertas & Ventanas | C10: 0.1 | D10: Lo que concierne a su correcta implementación y mantenimiento de las mismas. | E10: Contar con ventanas/puertas y en buen estado (no rotas, quiñadas).
B11: Baños | C11: 0.1 | D11: Lo que concierne a instalación de inodoros, lavamanos, duchas. | E11: Contar con baños y en óptimas condiciones para su funcionamiento.
B12: Pisos | C12: 0.1 | D12: Lo que concierne a pisos planos e instalados, sin huecos, etc. | E12: Contar con pisos en optimas condiciones para su funcionamiento.

Sheet Hoja3
